2025-02-20 06:38:12,078 - INFO - Waiting for database(s) to be ready ...
2025-02-20 06:38:12,078 - INFO - Host: odoo@db:5432
2025-02-20 06:38:12,078 - INFO - Timeout: 30 seconds
2025-02-20 06:38:12,081 - INFO - ðŸš€ Database(s) are ready.
2025-02-20 06:38:12,955 1 WARNING ? odoo.service.server: Could not set ARENA_MAX through mallopt()
2025-02-20 06:38:21,726 1 ERROR testing odoo.addons.base.tests.test_configmanager: FAIL: TestConfigManager.test_01_default_config
Traceback (most recent call last):
  File "/usr/local/lib/python3.12/site-packages/odoo/addons/base/tests/test_configmanager.py", line 143, in test_01_default_config
    self.assertEqual(config.options, default_values, "Options don't match")
AssertionError: {'adm[206 chars]cket_keep_alive_timeout': 3600, 'websocket_rat[1943 chars]: {}} != {'adm[206 chars]cket_rate_limit_burst': 10, 'websocket_rate_li[1990 chars]5536}
- {'addons_path': '/usr/local/lib/python3.12/site-packages/odoo/addons',
+ {'addons_path': '/usr/local/lib/python3.12/site-packages/odoo/addons,/usr/local/lib/python3.12/site-packages/addons',
   'admin_passwd': 'admin',
   'config': None,
   'csv_internal_sep': ',',
   'data_dir': '/home/odoo/.local/share/Odoo',
   'db_host': False,
   'db_maxconn': 64,
   'db_maxconn_gevent': False,
   'db_name': False,
   'db_password': False,
   'db_port': False,
   'db_replica_host': False,
   'db_replica_port': False,
   'db_sslmode': 'prefer',
   'db_template': 'template0',
   'db_user': False,
   'dbfilter': '',
   'demo': {},
   'dev_mode': [],
   'email_from': False,
   'from_filter': False,
   'geoip_city_db': '/usr/share/GeoIP/GeoLite2-City.mmdb',
   'geoip_country_db': '/usr/share/GeoIP/GeoLite2-Country.mmdb',
   'gevent_port': 8072,
   'http_enable': True,
   'http_interface': '',
   'http_port': 8069,
   'import_partial': '',
   'init': {},
   'language': None,
   'limit_memory_hard': 2684354560,
   'limit_memory_hard_gevent': False,
   'limit_memory_soft': 2147483648,
   'limit_memory_soft_gevent': False,
   'limit_request': 65536,
   'limit_time_cpu': 60,
   'limit_time_real': 120,
   'limit_time_real_cron': -1,
   'limit_time_worker_cron': 0,
   'list_db': True,
   'load_language': None,
   'log_db': False,
   'log_db_level': 'warning',
   'log_handler': [':INFO'],
   'log_level': 'info',
   'logfile': '',
   'max_cron_threads': 2,
   'osv_memory_count_limit': 0,
   'overwrite_existing_translations': False,
   'pg_path': '',
   'pidfile': '',
   'proxy_mode': False,
   'publisher_warranty_url': 'http://services.odoo.com/publisher-warranty/',
   'reportgz': False,
   'root_path': '/usr/local/lib/python3.12/site-packages/odoo',
   'save': None,
   'screencasts': '',
   'screenshots': '/tmp/odoo_tests',
   'server_wide_modules': 'base,web',
   'shell_interface': None,
   'smtp_password': False,
   'smtp_port': 25,
   'smtp_server': 'localhost',
   'smtp_ssl': False,
   'smtp_ssl_certificate_filename': False,
   'smtp_ssl_private_key_filename': False,
   'smtp_user': False,
   'stop_after_init': False,
   'syslog': False,
   'test_enable': False,
   'test_file': '',
   'test_tags': None,
   'transient_age_limit': 1.0,
   'translate_in': '',
   'translate_modules': ['all'],
   'translate_out': '',
   'unaccent': False,
   'update': {},
   'upgrade_path': '',
   'websocket_keep_alive_timeout': 3600,
   'websocket_rate_limit_burst': 10,
   'websocket_rate_limit_delay': 0.2,
   'without_demo': False,
   'workers': 0,
   'x_sendfile': False} : Options don't match

2025-02-20 06:38:21,732 1 ERROR testing odoo.addons.base.tests.test_configmanager: FAIL: TestConfigManager.test_03_save_default_options
Traceback (most recent call last):
  File "/usr/local/lib/python3.12/site-packages/odoo/addons/base/tests/test_configmanager.py", line 285, in test_03_save_default_options
    self.assertEqual(config_content.splitlines(), save_content.splitlines())
AssertionError: Lists differ: ['[op[70 chars]ddons', 'admin_passwd = admin', 'csv_internal_[1733 chars]lse'] != ['[op[70 chars]ddons,/usr/local/lib/python3.12/site-packages/[1780 chars]lse']

First differing element 1:
'addo[46 chars]ges/odoo/addons'
'addo[46 chars]ges/odoo/addons,/usr/local/lib/python3.12/site-packages/addons'

  ['[options]',
-  'addons_path = /usr/local/lib/python3.12/site-packages/odoo/addons',
+  'addons_path = '
+  '/usr/local/lib/python3.12/site-packages/odoo/addons,/usr/local/lib/python3.12/site-packages/addons',
   'admin_passwd = admin',
   'csv_internal_sep = ,',
   'data_dir = /home/odoo/.local/share/Odoo',
   'db_host = False',
   'db_maxconn = 64',
   'db_maxconn_gevent = False',
   'db_name = False',
   'db_password = False',
   'db_port = False',
   'db_replica_host = False',
   'db_replica_port = False',
   'db_sslmode = prefer',
   'db_template = template0',
   'db_user = False',
   'dbfilter = ',
   'demo = {}',
   'email_from = False',
   'from_filter = False',
   'geoip_city_db = /usr/share/GeoIP/GeoLite2-City.mmdb',
   'geoip_country_db = /usr/share/GeoIP/GeoLite2-Country.mmdb',
   'gevent_port = 8072',
   'http_enable = True',
   'http_interface = ',
   'http_port = 8069',
   'import_partial = ',
   'limit_memory_hard = 2684354560',
   'limit_memory_hard_gevent = False',
   'limit_memory_soft = 2147483648',
   'limit_memory_soft_gevent = False',
   'limit_request = 65536',
   'limit_time_cpu = 60',
   'limit_time_real = 120',
   'limit_time_real_cron = -1',
   'limit_time_worker_cron = 0',
   'list_db = True',
   'log_db = False',
   'log_db_level = warning',
   'log_handler = :INFO',
   'log_level = info',
   'logfile = ',
   'max_cron_threads = 2',
   'osv_memory_count_limit = 0',
   'pg_path = ',
   'pidfile = ',
   'proxy_mode = False',
   'reportgz = False',
   'screencasts = ',
   'screenshots = /tmp/odoo_tests',
   'server_wide_modules = base,web',
   'smtp_password = False',
   'smtp_port = 25',
   'smtp_server = localhost',
   'smtp_ssl = False',
   'smtp_ssl_certificate_filename = False',
   'smtp_ssl_private_key_filename = False',
   'smtp_user = False',
   'syslog = False',
   'test_enable = False',
   'test_file = ',
   'test_tags = None',
   'transient_age_limit = 1.0',
   "translate_modules = ['all']",
   'unaccent = False',
   'upgrade_path = ',
   'websocket_keep_alive_timeout = 3600',
   'websocket_rate_limit_burst = 10',
   'websocket_rate_limit_delay = 0.2',
   'without_demo = False',
   'workers = 0',
   'x_sendfile = False']

2025-02-20 06:38:21,737 1 ERROR testing odoo.addons.base.tests.test_configmanager: FAIL: TestConfigManager.test_04_odoo16_config_file
Traceback (most recent call last):
  File "/usr/local/lib/python3.12/site-packages/odoo/addons/base/tests/test_configmanager.py", line 394, in test_04_odoo16_config_file
    self.assertEqual(config.options, assert_options, "Options don't match")
AssertionError: {'adm[42 chars],', 'publisher_warranty_url': 'http://services[2113 chars]: {}} != {'adm[42 chars],', 'db_host': False, 'db_maxconn': 64, 'db_na[2160 chars]5536}
- {'addons_path': '/usr/local/lib/python3.12/site-packages/odoo/addons',
+ {'addons_path': '/usr/local/lib/python3.12/site-packages/odoo/addons,/usr/local/lib/python3.12/site-packages/addons',
   'admin_passwd': 'admin',
   'config': None,
   'csv_internal_sep': ',',
   'data_dir': '/home/odoo/.local/share/Odoo',
   'db_host': False,
   'db_maxconn': 64,
   'db_maxconn_gevent': False,
   'db_name': False,
   'db_password': False,
   'db_port': False,
   'db_replica_host': False,
   'db_replica_port': False,
   'db_sslmode': 'prefer',
   'db_template': 'template0',
   'db_user': False,
   'dbfilter': '',
   'demo': {},
   'dev_mode': [],
   'email_from': False,
   'from_filter': False,
   'geoip_city_db': '/usr/share/GeoIP/GeoLite2-City.mmdb',
   'geoip_country_db': '/usr/share/GeoIP/GeoLite2-Country.mmdb',
   'gevent_port': 8072,
   'http_enable': True,
   'http_interface': '',
   'http_port': 8069,
   'import_partial': '',
   'init': {},
   'language': None,
   'limit_memory_hard': 2684354560,
   'limit_memory_hard_gevent': False,
   'limit_memory_soft': 2147483648,
   'limit_memory_soft_gevent': False,
   'limit_request': 65536,
   'limit_time_cpu': 60,
   'limit_time_real': 120,
   'limit_time_real_cron': -1,
   'limit_time_worker_cron': 0,
   'list_db': True,
   'load_language': None,
   'log_db': False,
   'log_db_level': 'warning',
   'log_handler': [':INFO'],
   'log_level': 'info',
   'logfile': '',
   'max_cron_threads': 2,
   'osv_memory_count_limit': 0,
   'overwrite_existing_translations': False,
   'pg_path': '',
   'pidfile': '',
   'proxy_mode': False,
   'publisher_warranty_url': 'http://services.odoo.com/publisher-warranty/',
   'reportgz': False,
   'root_path': '/usr/local/lib/python3.12/site-packages/odoo',
   'save': None,
   'screencasts': '',
   'screenshots': '/tmp/odoo_tests',
   'server_wide_modules': 'base,web',
   'shell_interface': None,
   'smtp_password': False,
   'smtp_port': 25,
   'smtp_server': 'localhost',
   'smtp_ssl': False,
   'smtp_ssl_certificate_filename': False,
   'smtp_ssl_private_key_filename': False,
   'smtp_user': False,
   'stop_after_init': False,
   'syslog': False,
   'test_enable': False,
   'test_file': '',
   'test_tags': None,
   'transient_age_limit': 1.0,
   'translate_in': '',
   'translate_modules': ['all'],
   'translate_out': '',
   'unaccent': False,
   'update': {},
   'upgrade_path': '',
   'websocket_keep_alive_timeout': '3600',
   'websocket_rate_limit_burst': '10',
   'websocket_rate_limit_delay': '0.2',
   'without_demo': False,
   'workers': 0,
   'x_sendfile': False} : Options don't match

2025-02-20 06:38:21,744 1 ERROR testing odoo.addons.base.tests.test_configmanager: FAIL: TestConfigManager.test_06_cli
Traceback (most recent call last):
  File "/usr/local/lib/python3.12/site-packages/odoo/addons/base/tests/test_configmanager.py", line 530, in test_06_cli
    self.assertEqual(config.options, values)
AssertionError: {'adm[206 chars]cket_keep_alive_timeout': 3600, 'websocket_rat[2303 chars]: {}} != {'adm[206 chars]cket_rate_limit_burst': 10, 'websocket_rate_li[2350 chars] 100}
- {'addons_path': '/usr/local/lib/python3.12/site-packages/odoo/addons',
+ {'addons_path': '/usr/local/lib/python3.12/site-packages/odoo/addons,/usr/local/lib/python3.12/site-packages/addons',
   'admin_passwd': 'admin',
   'config': None,
   'csv_internal_sep': ',',
   'data_dir': '/tmp/data-dir',
   'db_host': 'db.localhost',
   'db_maxconn': 42,
   'db_maxconn_gevent': 100,
   'db_name': 'horizon',
   'db_password': 'Tigrou0073',
   'db_port': 4269,
   'db_replica_host': 'db2.localhost',
   'db_replica_port': 2038,
   'db_sslmode': 'verify-full',
   'db_template': 'backup1706',
   'db_user': 'kiwi',
   'dbfilter': '.*',
   'demo': {},
   'dev_mode': ['xml', 'reload'],
   'email_from': 'admin@example.com',
   'from_filter': '.*',
   'geoip_city_db': '/tmp/city.db',
   'geoip_country_db': '/tmp/country.db',
   'gevent_port': 8012,
   'http_enable': False,
   'http_interface': '10.0.0.254',
   'http_port': 6942,
   'import_partial': '/tmp/import-partial',
   'init': {'hr': 1, 'stock': 1},
   'language': 'fr_FR',
   'limit_memory_hard': 1048578,
   'limit_memory_hard_gevent': 1048579,
   'limit_memory_soft': 1048576,
   'limit_memory_soft_gevent': 1048577,
   'limit_request': 100,
   'limit_time_cpu': 60,
   'limit_time_real': 61,
   'limit_time_real_cron': 62,
   'limit_time_worker_cron': 0,
   'list_db': False,
   'load_language': 'fr_FR',
   'log_db': 'logdb',
   'log_db_level': 'debug',
   'log_handler': [':INFO',
                   'odoo.tools.config:DEBUG',
                   ':WARNING',
                   'odoo.http:DEBUG',
                   'odoo.sql_db:DEBUG'],
   'log_level': 'debug',
   'logfile': '/tmp/odoo.log',
   'max_cron_threads': 4,
   'osv_memory_count_limit': 71,
   'overwrite_existing_translations': True,
   'pg_path': '/tmp/pg_path',
   'pidfile': '/tmp/pidfile',
   'proxy_mode': True,
   'publisher_warranty_url': 'http://services.odoo.com/publisher-warranty/',
   'reportgz': False,
   'root_path': '/usr/local/lib/python3.12/site-packages/odoo',
   'save': None,
   'screencasts': '/tmp/screencasts',
   'screenshots': '/tmp/screenshots',
   'server_wide_modules': 'base,mail',
   'shell_interface': 'ipython',
   'smtp_password': 'Tigrou0072',
   'smtp_port': 1299,
   'smtp_server': 'smtp.localhost',
   'smtp_ssl': True,
   'smtp_ssl_certificate_filename': '/tmp/tlscert',
   'smtp_ssl_private_key_filename': '/tmp/tlskey',
   'smtp_user': 'spongebob',
   'stop_after_init': True,
   'syslog': False,
   'test_enable': True,
   'test_file': '/tmp/file-file',
   'test_tags': ':TestMantra.test_is_extra_mile_done',
   'transient_age_limit': 4.0,
   'translate_in': '/tmp/translate_in.csv',
   'translate_modules': ['hr', 'mail', 'stock'],
   'translate_out': '/tmp/translate_out.csv',
   'unaccent': True,
   'update': {'account': 1, 'website': 1},
   'upgrade_path': '',
   'websocket_keep_alive_timeout': 3600,
   'websocket_rate_limit_burst': 10,
   'websocket_rate_limit_delay': 0.2,
   'without_demo': 'rigolo',
   'workers': 92,
   'x_sendfile': True}

2025-02-20 06:38:21,746 1 WARNING testing odoo.modules.registry: Failed to open a readonly cursor, falling back to read-write cursor
2025-02-20 06:38:21,747 1 ERROR testing odoo.addons.base.tests.test_db_cursor: FAIL: TestRealCursor.test_connection_readonly
Traceback (most recent call last):
  File "/usr/local/lib/python3.12/site-packages/odoo/addons/base/tests/test_db_cursor.py", line 64, in test_connection_readonly
    self.assertEqual(cr.fetchone(), ('on',))
AssertionError: Tuples differ: ('off',) != ('on',)

First differing element 0:
'off'
'on'

- ('off',)
?    ^^

+ ('on',)
?    ^


2025-02-20 06:38:22,690 1 ERROR testing odoo.addons.base.tests.test_expression: FAIL: TestExpression.test_invalid
ValueError: time data 'foo' does not match format '%'

During handling of the above exception, another exception occurred:

Traceback (most recent call last):
  File "/usr/local/lib/python3.12/site-packages/odoo/tools/misc.py", line 786, in deco
    return func(*args, **kwargs)
           ^^^^^^^^^^^^^^^^^^^^^
  File "/usr/local/lib/python3.12/site-packages/odoo/addons/base/tests/test_expression.py", line 1004, in test_invalid
    with self.assertRaisesRegex(ValueError, r"^stray % in format '%'$"):
         ^^^^^^^^^^^^^^^^^^^^^^^^^^^^^^^^^^^^^^^^^^^^^^^^^^^^^^^^^^^^^^
AssertionError: "^stray % in format '%'$" does not match "time data 'foo' does not match format '%'"

2025-02-20 06:38:31,669 1 ERROR testing odoo.addons.base.tests.test_mimetypes: FAIL: test_guess_mimetype.test_mimetype_get_extension
Traceback (most recent call last):
  File "/usr/local/lib/python3.12/site-packages/odoo/addons/base/tests/test_mimetypes.py", line 137, in test_mimetype_get_extension
    self.assertEqual(get_extension('filename.torrent'), '.torrent')
AssertionError: '' != '.torrent'
+ .torrent


2025-02-20 06:38:32,528 1 ERROR testing odoo.addons.base.tests.test_qweb: ERROR: TestQWebBasic.test_render_barcode
Traceback (most recent call last):
  File "/usr/local/lib/python3.12/site-packages/reportlab/graphics/renderPM.py", line 43, in _getPMBackend
    import rlPyCairo as M
ModuleNotFoundError: No module named 'rlPyCairo'

During handling of the above exception, another exception occurred:

Traceback (most recent call last):
  File "/usr/local/lib/python3.12/site-packages/reportlab/graphics/renderPM.py", line 46, in _getPMBackend
    import _rl_renderPM as M
ModuleNotFoundError: No module named '_rl_renderPM'

During handling of the above exception, another exception occurred:

Traceback (most recent call last):
  File "<2025>", line 51, in template_2025
  File "<2025>", line 11, in template_2025_content
  File "/usr/local/lib/python3.12/site-packages/odoo/addons/base/models/ir_qweb.py", line 2452, in _get_field
    content = converter.record_to_html(record, field_name, field_options)
              ^^^^^^^^^^^^^^^^^^^^^^^^^^^^^^^^^^^^^^^^^^^^^^^^^^^^^^^^^^^
  File "/usr/local/lib/python3.12/site-packages/odoo/addons/base/models/ir_qweb_fields.py", line 135, in record_to_html
    return False if value is False else self.value_to_html(value, options=options)
                                        ^^^^^^^^^^^^^^^^^^^^^^^^^^^^^^^^^^^^^^^^^^
  File "/usr/local/lib/python3.12/site-packages/odoo/addons/base/models/ir_qweb_fields.py", line 742, in value_to_html
    barcode = self.env['ir.actions.report'].barcode(
              ^^^^^^^^^^^^^^^^^^^^^^^^^^^^^^^^^^^^^^
  File "/usr/local/lib/python3.12/site-packages/odoo/addons/base/models/ir_actions_report.py", line 727, in barcode
    return barcode.asString('png')
           ^^^^^^^^^^^^^^^^^^^^^^^
  File "/usr/local/lib/python3.12/site-packages/reportlab/graphics/shapes.py", line 803, in asString
    return renderPM.drawToString(self, fmt=format,showBoundary=getattr(self,'showBorder',
           ^^^^^^^^^^^^^^^^^^^^^^^^^^^^^^^^^^^^^^^^^^^^^^^^^^^^^^^^^^^^^^^^^^^^^^^^^^^^^^
  File "/usr/local/lib/python3.12/site-packages/reportlab/graphics/renderPM.py", line 721, in drawToString
    drawToFile(d,s,fmt=fmt, dpi=dpi, bg=bg, configPIL=configPIL,backend=backend)
  File "/usr/local/lib/python3.12/site-packages/reportlab/graphics/renderPM.py", line 716, in drawToFile
    c = drawToPMCanvas(d, dpi=dpi, bg=bg, configPIL=configPIL, showBoundary=showBoundary,backend=backend)
        ^^^^^^^^^^^^^^^^^^^^^^^^^^^^^^^^^^^^^^^^^^^^^^^^^^^^^^^^^^^^^^^^^^^^^^^^^^^^^^^^^^^^^^^^^^^^^^^^^
  File "/usr/local/lib/python3.12/site-packages/reportlab/graphics/renderPM.py", line 701, in drawToPMCanvas
    c = PMCanvas(d.width, d.height, dpi=dpi, bg=bg, configPIL=configPIL, backend=backend)
        ^^^^^^^^^^^^^^^^^^^^^^^^^^^^^^^^^^^^^^^^^^^^^^^^^^^^^^^^^^^^^^^^^^^^^^^^^^^^^^^^^
  File "/usr/local/lib/python3.12/site-packages/reportlab/graphics/renderPM.py", line 304, in __init__
    self.__dict__['_gs'] = self._getGState(w,h,bg,backend)
                           ^^^^^^^^^^^^^^^^^^^^^^^^^^^^^^^
  File "/usr/local/lib/python3.12/site-packages/reportlab/graphics/renderPM.py", line 317, in _getGState
    mod = _getPMBackend(backend)
          ^^^^^^^^^^^^^^^^^^^^^^
  File "/usr/local/lib/python3.12/site-packages/reportlab/graphics/renderPM.py", line 48, in _getPMBackend
    raise RenderPMError(f"""cannot import desired renderPM backend {backend}
reportlab.graphics.utils.RenderPMError: cannot import desired renderPM backend rlPyCairo
Seek advice at the users list see
https://pairlist2.pair.net/mailman/listinfo/reportlab-users

The above exception was the direct cause of the following exception:

Traceback (most recent call last):
  File "/usr/local/lib/python3.12/site-packages/odoo/addons/base/tests/test_qweb.py", line 1606, in test_render_barcode
    rendered = self.env['ir.qweb']._render(view.id, values={'partner': partner}).strip()
               ^^^^^^^^^^^^^^^^^^^^^^^^^^^^^^^^^^^^^^^^^^^^^^^^^^^^^^^^^^^^^^^^^
  File "/usr/local/lib/python3.12/site-packages/odoo/tools/profiler.py", line 306, in _tracked_method_render
    return method_render(self, template, values, **options)
           ^^^^^^^^^^^^^^^^^^^^^^^^^^^^^^^^^^^^^^^^^^^^^^^^
  File "/usr/local/lib/python3.12/site-packages/odoo/addons/base/models/ir_qweb.py", line 606, in _render
    result = ''.join(rendering)
             ^^^^^^^^^^^^^^^^^^
  File "<2025>", line 59, in template_2025
odoo.addons.base.models.ir_qweb.QWebException: Error while render the template
RenderPMError: cannot import desired renderPM backend rlPyCairo
Seek advice at the users list see
https://pairlist2.pair.net/mailman/listinfo/reportlab-users
Template: 2025
Path: /div
Node: <div t-field="partner.barcode" t-options="{\'widget\': \'barcode\', \'width\': 100, \'height\': 30}"/>

2025-02-20 06:38:36,389 1 ERROR testing odoo.addons.base.tests.test_upgrade_code: ERROR: TestCommand.test_upgrade_code_example
Traceback (most recent call last):
  File "/usr/local/lib/python3.12/site-packages/odoo/addons/base/tests/test_upgrade_code.py", line 31, in test_upgrade_code_example
    proc = self.run_command('upgrade_code', '--script', '17.5-00-example', '--dry-run')
           ^^^^^^^^^^^^^^^^^^^^^^^^^^^^^^^^^^^^^^^^^^^^^^^^^^^^^^^^^^^^^^^^^^^^^^^^^^^^
  File "/usr/local/lib/python3.12/site-packages/odoo/addons/base/tests/test_upgrade_code.py", line 17, in run_command
    return sp.run(
           ^^^^^^^
  File "/usr/local/lib/python3.12/subprocess.py", line 573, in run
    raise CalledProcessError(retcode, process.args,
subprocess.CalledProcessError: Command '['/usr/local/bin/python3.12', '/usr/local/lib/python3.12/site-packages/odoo-bin', '--addons-path=/odoo/addons,/volumes/addons', 'upgrade_code', '--script', '17.5-00-example', '--dry-run']' returned non-zero exit status 2.

2025-02-20 06:38:36,403 1 ERROR testing odoo.addons.base.tests.test_upgrade_code: ERROR: TestCommand.test_upgrade_code_help
Traceback (most recent call last):
  File "/usr/local/lib/python3.12/site-packages/odoo/addons/base/tests/test_upgrade_code.py", line 36, in test_upgrade_code_help
    proc = self.run_command('upgrade_code', '--help')
           ^^^^^^^^^^^^^^^^^^^^^^^^^^^^^^^^^^^^^^^^^^
  File "/usr/local/lib/python3.12/site-packages/odoo/addons/base/tests/test_upgrade_code.py", line 17, in run_command
    return sp.run(
           ^^^^^^^
  File "/usr/local/lib/python3.12/subprocess.py", line 573, in run
    raise CalledProcessError(retcode, process.args,
subprocess.CalledProcessError: Command '['/usr/local/bin/python3.12', '/usr/local/lib/python3.12/site-packages/odoo-bin', '--addons-path=/odoo/addons,/volumes/addons', 'upgrade_code', '--help']' returned non-zero exit status 2.

2025-02-20 06:38:41,150 1 ERROR testing odoo.modules.loading: Module base: 7 failures, 3 errors of 989 tests
2025-02-20 06:38:41,150 1 INFO testing odoo.modules.loading: 1 modules loaded in 28.05s, 8193 queries (+35255 extra)
2025-02-20 06:38:43,216 1 ERROR testing odoo.addons.base.models.ir_model: Missing model web_tour.tour
2025-02-20 06:38:43,216 1 ERROR testing odoo.addons.base.models.ir_model: Missing model iap.account
2025-02-20 06:38:43,347 1 ERROR testing odoo.addons.base.models.ir_model: Missing model web_tour.tour
2025-02-20 06:38:43,348 1 ERROR testing odoo.addons.base.models.ir_model: Missing model iap.account
2025-02-20 06:38:43,676 1 ERROR testing odoo.http: Exception during request handling.
Traceback (most recent call last):
  File "/usr/local/lib/python3.12/site-packages/odoo/http.py", line 2371, in __call__
    response = request._serve_db()
               ^^^^^^^^^^^^^^^^^^^
  File "/usr/local/lib/python3.12/site-packages/odoo/http.py", line 1898, in _serve_db
    return self._transactioning(
           ^^^^^^^^^^^^^^^^^^^^^
  File "/usr/local/lib/python3.12/site-packages/odoo/http.py", line 1961, in _transactioning
    return service_model.retrying(func, env=self.env)
           ^^^^^^^^^^^^^^^^^^^^^^^^^^^^^^^^^^^^^^^^^^
  File "/usr/local/lib/python3.12/site-packages/odoo/service/model.py", line 137, in retrying
    result = func()
             ^^^^^^
  File "/usr/local/lib/python3.12/site-packages/odoo/http.py", line 1928, in _serve_ir_http
    response = self.dispatcher.dispatch(rule.endpoint, args)
               ^^^^^^^^^^^^^^^^^^^^^^^^^^^^^^^^^^^^^^^^^^^^^
  File "/usr/local/lib/python3.12/site-packages/odoo/http.py", line 2089, in dispatch
    return self.request.registry['ir.http']._dispatch(endpoint)
           ^^^^^^^^^^^^^^^^^^^^^^^^^^^^^^^^^^^^^^^^^^^^^^^^^^^^
  File "/usr/local/lib/python3.12/site-packages/odoo/addons/base/models/ir_http.py", line 329, in _dispatch
    result = endpoint(**request.params)
             ^^^^^^^^^^^^^^^^^^^^^^^^^^
  File "/usr/local/lib/python3.12/site-packages/odoo/http.py", line 727, in route_wrapper
    result = endpoint(self, *args, **params_ok)
             ^^^^^^^^^^^^^^^^^^^^^^^^^^^^^^^^^^
  File "/odoo/addons/web/controllers/binary.py", line 149, in content_assets
    stream = env['ir.binary']._get_stream_from(attachment, 'raw', filename)
             ^^^^^^^^^^^^^^^^^^^^^^^^^^^^^^^^^^^^^^^^^^^^^^^^^^^^^^^^^^^^^^
  File "/usr/local/lib/python3.12/site-packages/odoo/addons/base/models/ir_binary.py", line 127, in _get_stream_from
    stream = self._record_to_stream(record, field_name)
             ^^^^^^^^^^^^^^^^^^^^^^^^^^^^^^^^^^^^^^^^^^
  File "/usr/local/lib/python3.12/site-packages/odoo/addons/base/models/ir_binary.py", line 74, in _record_to_stream
    return record._to_http_stream()
           ^^^^^^^^^^^^^^^^^^^^^^^^
  File "/usr/local/lib/python3.12/site-packages/odoo/addons/base/models/ir_attachment.py", line 797, in _to_http_stream
    stat = os.stat(stream.path)
           ^^^^^^^^^^^^^^^^^^^^
FileNotFoundError: [Errno 2] No such file or directory: '/volumes/data/filestore/testing/4a/4a2b926a8affea412de805d420481fc6ef1408f6'
2025-02-20 06:38:45,249 1 ERROR testing odoo.http: Exception during request handling.
Traceback (most recent call last):
  File "/usr/local/lib/python3.12/site-packages/odoo/http.py", line 2371, in __call__
    response = request._serve_db()
               ^^^^^^^^^^^^^^^^^^^
  File "/usr/local/lib/python3.12/site-packages/odoo/http.py", line 1898, in _serve_db
    return self._transactioning(
           ^^^^^^^^^^^^^^^^^^^^^
  File "/usr/local/lib/python3.12/site-packages/odoo/http.py", line 1961, in _transactioning
    return service_model.retrying(func, env=self.env)
           ^^^^^^^^^^^^^^^^^^^^^^^^^^^^^^^^^^^^^^^^^^
  File "/usr/local/lib/python3.12/site-packages/odoo/service/model.py", line 137, in retrying
    result = func()
             ^^^^^^
  File "/usr/local/lib/python3.12/site-packages/odoo/http.py", line 1928, in _serve_ir_http
    response = self.dispatcher.dispatch(rule.endpoint, args)
               ^^^^^^^^^^^^^^^^^^^^^^^^^^^^^^^^^^^^^^^^^^^^^
  File "/usr/local/lib/python3.12/site-packages/odoo/http.py", line 2089, in dispatch
    return self.request.registry['ir.http']._dispatch(endpoint)
           ^^^^^^^^^^^^^^^^^^^^^^^^^^^^^^^^^^^^^^^^^^^^^^^^^^^^
  File "/usr/local/lib/python3.12/site-packages/odoo/addons/base/models/ir_http.py", line 329, in _dispatch
    result = endpoint(**request.params)
             ^^^^^^^^^^^^^^^^^^^^^^^^^^
  File "/usr/local/lib/python3.12/site-packages/odoo/http.py", line 727, in route_wrapper
    result = endpoint(self, *args, **params_ok)
             ^^^^^^^^^^^^^^^^^^^^^^^^^^^^^^^^^^
  File "/odoo/addons/web/controllers/binary.py", line 149, in content_assets
    stream = env['ir.binary']._get_stream_from(attachment, 'raw', filename)
             ^^^^^^^^^^^^^^^^^^^^^^^^^^^^^^^^^^^^^^^^^^^^^^^^^^^^^^^^^^^^^^
  File "/usr/local/lib/python3.12/site-packages/odoo/addons/base/models/ir_binary.py", line 127, in _get_stream_from
    stream = self._record_to_stream(record, field_name)
             ^^^^^^^^^^^^^^^^^^^^^^^^^^^^^^^^^^^^^^^^^^
  File "/usr/local/lib/python3.12/site-packages/odoo/addons/base/models/ir_binary.py", line 74, in _record_to_stream
    return record._to_http_stream()
           ^^^^^^^^^^^^^^^^^^^^^^^^
  File "/usr/local/lib/python3.12/site-packages/odoo/addons/base/models/ir_attachment.py", line 797, in _to_http_stream
    stat = os.stat(stream.path)
           ^^^^^^^^^^^^^^^^^^^^
FileNotFoundError: [Errno 2] No such file or directory: '/volumes/data/filestore/testing/4a/4a2b926a8affea412de805d420481fc6ef1408f6'
2025-02-20 06:38:46,277 1 WARNING testing odoo.addons.base.models.ir_actions_report: wkhtmltopdf: Exit with code 1 due to network error: UnknownContentError

2025-02-20 06:38:46,305 1 ERROR testing odoo.http: Exception during request handling.
Traceback (most recent call last):
  File "/usr/local/lib/python3.12/site-packages/odoo/http.py", line 2371, in __call__
    response = request._serve_db()
               ^^^^^^^^^^^^^^^^^^^
  File "/usr/local/lib/python3.12/site-packages/odoo/http.py", line 1898, in _serve_db
    return self._transactioning(
           ^^^^^^^^^^^^^^^^^^^^^
  File "/usr/local/lib/python3.12/site-packages/odoo/http.py", line 1961, in _transactioning
    return service_model.retrying(func, env=self.env)
           ^^^^^^^^^^^^^^^^^^^^^^^^^^^^^^^^^^^^^^^^^^
  File "/usr/local/lib/python3.12/site-packages/odoo/service/model.py", line 137, in retrying
    result = func()
             ^^^^^^
  File "/usr/local/lib/python3.12/site-packages/odoo/http.py", line 1928, in _serve_ir_http
    response = self.dispatcher.dispatch(rule.endpoint, args)
               ^^^^^^^^^^^^^^^^^^^^^^^^^^^^^^^^^^^^^^^^^^^^^
  File "/usr/local/lib/python3.12/site-packages/odoo/http.py", line 2089, in dispatch
    return self.request.registry['ir.http']._dispatch(endpoint)
           ^^^^^^^^^^^^^^^^^^^^^^^^^^^^^^^^^^^^^^^^^^^^^^^^^^^^
  File "/usr/local/lib/python3.12/site-packages/odoo/addons/base/models/ir_http.py", line 329, in _dispatch
    result = endpoint(**request.params)
             ^^^^^^^^^^^^^^^^^^^^^^^^^^
  File "/usr/local/lib/python3.12/site-packages/odoo/http.py", line 727, in route_wrapper
    result = endpoint(self, *args, **params_ok)
             ^^^^^^^^^^^^^^^^^^^^^^^^^^^^^^^^^^
  File "/odoo/addons/web/controllers/binary.py", line 149, in content_assets
    stream = env['ir.binary']._get_stream_from(attachment, 'raw', filename)
             ^^^^^^^^^^^^^^^^^^^^^^^^^^^^^^^^^^^^^^^^^^^^^^^^^^^^^^^^^^^^^^
  File "/usr/local/lib/python3.12/site-packages/odoo/addons/base/models/ir_binary.py", line 127, in _get_stream_from
    stream = self._record_to_stream(record, field_name)
             ^^^^^^^^^^^^^^^^^^^^^^^^^^^^^^^^^^^^^^^^^^
  File "/usr/local/lib/python3.12/site-packages/odoo/addons/base/models/ir_binary.py", line 74, in _record_to_stream
    return record._to_http_stream()
           ^^^^^^^^^^^^^^^^^^^^^^^^
  File "/usr/local/lib/python3.12/site-packages/odoo/addons/base/models/ir_attachment.py", line 797, in _to_http_stream
    stat = os.stat(stream.path)
           ^^^^^^^^^^^^^^^^^^^^
FileNotFoundError: [Errno 2] No such file or directory: '/volumes/data/filestore/testing/4a/4a2b926a8affea412de805d420481fc6ef1408f6'
2025-02-20 06:38:47,339 1 ERROR testing odoo.http: Exception during request handling.
Traceback (most recent call last):
  File "/usr/local/lib/python3.12/site-packages/odoo/http.py", line 2371, in __call__
    response = request._serve_db()
               ^^^^^^^^^^^^^^^^^^^
  File "/usr/local/lib/python3.12/site-packages/odoo/http.py", line 1898, in _serve_db
    return self._transactioning(
           ^^^^^^^^^^^^^^^^^^^^^
  File "/usr/local/lib/python3.12/site-packages/odoo/http.py", line 1961, in _transactioning
    return service_model.retrying(func, env=self.env)
           ^^^^^^^^^^^^^^^^^^^^^^^^^^^^^^^^^^^^^^^^^^
  File "/usr/local/lib/python3.12/site-packages/odoo/service/model.py", line 137, in retrying
    result = func()
             ^^^^^^
  File "/usr/local/lib/python3.12/site-packages/odoo/http.py", line 1928, in _serve_ir_http
    response = self.dispatcher.dispatch(rule.endpoint, args)
               ^^^^^^^^^^^^^^^^^^^^^^^^^^^^^^^^^^^^^^^^^^^^^
  File "/usr/local/lib/python3.12/site-packages/odoo/http.py", line 2089, in dispatch
    return self.request.registry['ir.http']._dispatch(endpoint)
           ^^^^^^^^^^^^^^^^^^^^^^^^^^^^^^^^^^^^^^^^^^^^^^^^^^^^
  File "/usr/local/lib/python3.12/site-packages/odoo/addons/base/models/ir_http.py", line 329, in _dispatch
    result = endpoint(**request.params)
             ^^^^^^^^^^^^^^^^^^^^^^^^^^
  File "/usr/local/lib/python3.12/site-packages/odoo/http.py", line 727, in route_wrapper
    result = endpoint(self, *args, **params_ok)
             ^^^^^^^^^^^^^^^^^^^^^^^^^^^^^^^^^^
  File "/odoo/addons/web/controllers/binary.py", line 149, in content_assets
    stream = env['ir.binary']._get_stream_from(attachment, 'raw', filename)
             ^^^^^^^^^^^^^^^^^^^^^^^^^^^^^^^^^^^^^^^^^^^^^^^^^^^^^^^^^^^^^^
  File "/usr/local/lib/python3.12/site-packages/odoo/addons/base/models/ir_binary.py", line 127, in _get_stream_from
    stream = self._record_to_stream(record, field_name)
             ^^^^^^^^^^^^^^^^^^^^^^^^^^^^^^^^^^^^^^^^^^
  File "/usr/local/lib/python3.12/site-packages/odoo/addons/base/models/ir_binary.py", line 74, in _record_to_stream
    return record._to_http_stream()
           ^^^^^^^^^^^^^^^^^^^^^^^^
  File "/usr/local/lib/python3.12/site-packages/odoo/addons/base/models/ir_attachment.py", line 797, in _to_http_stream
    stat = os.stat(stream.path)
           ^^^^^^^^^^^^^^^^^^^^
FileNotFoundError: [Errno 2] No such file or directory: '/volumes/data/filestore/testing/4a/4a2b926a8affea412de805d420481fc6ef1408f6'
2025-02-20 06:38:48,375 1 WARNING testing odoo.addons.base.models.ir_actions_report: wkhtmltopdf: Exit with code 1 due to network error: UnknownContentError

2025-02-20 06:38:48,524 1 ERROR testing odoo.addons.web.tests.test_router: FAIL: Subtest TestWebRouter.test_router_get_action_triples_exist (path='users/1/res.partner/2')
Traceback (most recent call last):
  File "/odoo/addons/web/tests/test_router.py", line 67, in test_router_get_action_triples_exist
    self.assertEqual(list(get_action_triples(self.env, path)), triples)
AssertionError: Lists differ: [(None, ir.actions.act_window(70,), 1), (1, ir.actions.act_window(57,), 2)] != [(None, ir.actions.act_window(70,), 1), (1, ir.actions.act_window(56,), 2)]

First differing element 1:
(1, ir.actions.act_window(57,), 2)
(1, ir.actions.act_window(56,), 2)

- [(None, ir.actions.act_window(70,), 1), (1, ir.actions.act_window(57,), 2)]
?                                                                    ^

+ [(None, ir.actions.act_window(70,), 1), (1, ir.actions.act_window(56,), 2)]
?                                                                    ^


2025-02-20 06:38:48,834 1 ERROR testing odoo.addons.base.models.ir_model: Missing model web_tour.tour
2025-02-20 06:38:48,835 1 ERROR testing odoo.addons.base.models.ir_model: Missing model iap.account
2025-02-20 06:38:48,884 1 ERROR testing odoo.tests.suite: ERROR: setUpClass (odoo.addons.web.tests.test_translate.TestTranslationOverride)
Traceback (most recent call last):
  File "/odoo/addons/web/tests/test_translate.py", line 11, in setUpClass
    cls.custom = cls.env['ir.model.fields'].create({
                 ^^^^^^^^^^^^^^^^^^^^^^^^^^^^^^^^^^^
  File "<decorator-gen-2>", line 2, in create
  File "/usr/local/lib/python3.12/site-packages/odoo/api.py", line 479, in _model_create_multi
    return create(self, [arg])
           ^^^^^^^^^^^^^^^^^^^
  File "/usr/local/lib/python3.12/site-packages/odoo/addons/base/models/ir_model.py", line 1025, in create
    vals['model'] = IrModel.browse(vals['model_id']).model
                    ^^^^^^^^^^^^^^^^^^^^^^^^^^^^^^^^^^^^^^
  File "/usr/local/lib/python3.12/site-packages/odoo/fields.py", line 1272, in __get__
    raise MissingError("\n".join([
odoo.exceptions.MissingError: Record does not exist or has been deleted.
(Record: ir.model(250,), User: 1)

2025-02-20 06:38:49,105 1 ERROR testing odoo.modules.loading: Module web: 1 failures, 1 errors of 20 tests
2025-02-20 06:38:52,458 1 INFO testing odoo.modules.loading: 12 modules loaded in 10.92s, 4198 queries (+7590 extra)
2025-02-20 06:38:52,639 1 ERROR testing odoo.modules.loading: At least one test failed when loading the modules.
2025-02-20 06:38:52,652 1 INFO testing odoo.addons.base.models.ir_qweb: Pregenerating assets bundles
2025-02-20 06:38:54,222 1 INFO testing odoo.addons.base.tests.test_http_case: skipped TestHttpCase.test_console_log_object : websocket-client module is not installed
2025-02-20 06:38:54,229 1 WARNING testing odoo.addons.base.tests.test_http_case.TestChromeBrowser.test_screencasts: websocket-client module is not installed
2025-02-20 06:38:54,736 1 WARNING testing odoo.addons.base.tests.test_ir_model.TestIrModelFieldsTranslation.test_ir_model_fields_translation: websocket-client module is not installed
2025-02-20 06:38:54,749 1 ERROR testing odoo.addons.base.tests.test_ormcache: FAIL: TestOrmCache.test_signaling_01_multiple
Traceback (most recent call last):
  File "/usr/local/lib/python3.12/site-packages/odoo/addons/base/tests/test_ormcache.py", line 186, in test_signaling_01_multiple
    with self.assertLogs() as logs:
         ^^^^^^^^^^^^^^^^^
  File "/usr/local/lib/python3.12/unittest/_log.py", line 84, in __exit__
    self._raiseFailure(
AssertionError: no logs of level INFO or higher triggered on root

2025-02-20 06:38:54,752 1 ERROR testing odoo.addons.base.tests.test_ormcache: FAIL: TestOrmCache.test_signaling_01_single
Traceback (most recent call last):
  File "/usr/local/lib/python3.12/site-packages/odoo/addons/base/tests/test_ormcache.py", line 147, in test_signaling_01_single
    with self.assertLogs() as logs:
         ^^^^^^^^^^^^^^^^^
  File "/usr/local/lib/python3.12/unittest/_log.py", line 84, in __exit__
    self._raiseFailure(
AssertionError: no logs of level INFO or higher triggered on root

2025-02-20 06:38:55,367 1 ERROR testing odoo.http: Exception during request handling.
Traceback (most recent call last):
  File "/usr/local/lib/python3.12/site-packages/odoo/http.py", line 2371, in __call__
    response = request._serve_db()
               ^^^^^^^^^^^^^^^^^^^
  File "/usr/local/lib/python3.12/site-packages/odoo/http.py", line 1898, in _serve_db
    return self._transactioning(
           ^^^^^^^^^^^^^^^^^^^^^
  File "/usr/local/lib/python3.12/site-packages/odoo/http.py", line 1961, in _transactioning
    return service_model.retrying(func, env=self.env)
           ^^^^^^^^^^^^^^^^^^^^^^^^^^^^^^^^^^^^^^^^^^
  File "/usr/local/lib/python3.12/site-packages/odoo/service/model.py", line 137, in retrying
    result = func()
             ^^^^^^
  File "/usr/local/lib/python3.12/site-packages/odoo/http.py", line 1928, in _serve_ir_http
    response = self.dispatcher.dispatch(rule.endpoint, args)
               ^^^^^^^^^^^^^^^^^^^^^^^^^^^^^^^^^^^^^^^^^^^^^
  File "/usr/local/lib/python3.12/site-packages/odoo/http.py", line 2089, in dispatch
    return self.request.registry['ir.http']._dispatch(endpoint)
           ^^^^^^^^^^^^^^^^^^^^^^^^^^^^^^^^^^^^^^^^^^^^^^^^^^^^
  File "/usr/local/lib/python3.12/site-packages/odoo/addons/base/models/ir_http.py", line 329, in _dispatch
    result = endpoint(**request.params)
             ^^^^^^^^^^^^^^^^^^^^^^^^^^
  File "/usr/local/lib/python3.12/site-packages/odoo/http.py", line 727, in route_wrapper
    result = endpoint(self, *args, **params_ok)
             ^^^^^^^^^^^^^^^^^^^^^^^^^^^^^^^^^^
  File "/odoo/addons/web/controllers/binary.py", line 149, in content_assets
    stream = env['ir.binary']._get_stream_from(attachment, 'raw', filename)
             ^^^^^^^^^^^^^^^^^^^^^^^^^^^^^^^^^^^^^^^^^^^^^^^^^^^^^^^^^^^^^^
  File "/usr/local/lib/python3.12/site-packages/odoo/addons/base/models/ir_binary.py", line 127, in _get_stream_from
    stream = self._record_to_stream(record, field_name)
             ^^^^^^^^^^^^^^^^^^^^^^^^^^^^^^^^^^^^^^^^^^
  File "/usr/local/lib/python3.12/site-packages/odoo/addons/base/models/ir_binary.py", line 74, in _record_to_stream
    return record._to_http_stream()
           ^^^^^^^^^^^^^^^^^^^^^^^^
  File "/usr/local/lib/python3.12/site-packages/odoo/addons/base/models/ir_attachment.py", line 797, in _to_http_stream
    stat = os.stat(stream.path)
           ^^^^^^^^^^^^^^^^^^^^
FileNotFoundError: [Errno 2] No such file or directory: '/volumes/data/filestore/testing/4a/4a2b926a8affea412de805d420481fc6ef1408f6'
2025-02-20 06:38:56,397 1 ERROR testing odoo.http: Exception during request handling.
Traceback (most recent call last):
  File "/usr/local/lib/python3.12/site-packages/odoo/http.py", line 2371, in __call__
    response = request._serve_db()
               ^^^^^^^^^^^^^^^^^^^
  File "/usr/local/lib/python3.12/site-packages/odoo/http.py", line 1898, in _serve_db
    return self._transactioning(
           ^^^^^^^^^^^^^^^^^^^^^
  File "/usr/local/lib/python3.12/site-packages/odoo/http.py", line 1961, in _transactioning
    return service_model.retrying(func, env=self.env)
           ^^^^^^^^^^^^^^^^^^^^^^^^^^^^^^^^^^^^^^^^^^
  File "/usr/local/lib/python3.12/site-packages/odoo/service/model.py", line 137, in retrying
    result = func()
             ^^^^^^
  File "/usr/local/lib/python3.12/site-packages/odoo/http.py", line 1928, in _serve_ir_http
    response = self.dispatcher.dispatch(rule.endpoint, args)
               ^^^^^^^^^^^^^^^^^^^^^^^^^^^^^^^^^^^^^^^^^^^^^
  File "/usr/local/lib/python3.12/site-packages/odoo/http.py", line 2089, in dispatch
    return self.request.registry['ir.http']._dispatch(endpoint)
           ^^^^^^^^^^^^^^^^^^^^^^^^^^^^^^^^^^^^^^^^^^^^^^^^^^^^
  File "/usr/local/lib/python3.12/site-packages/odoo/addons/base/models/ir_http.py", line 329, in _dispatch
    result = endpoint(**request.params)
             ^^^^^^^^^^^^^^^^^^^^^^^^^^
  File "/usr/local/lib/python3.12/site-packages/odoo/http.py", line 727, in route_wrapper
    result = endpoint(self, *args, **params_ok)
             ^^^^^^^^^^^^^^^^^^^^^^^^^^^^^^^^^^
  File "/odoo/addons/web/controllers/binary.py", line 149, in content_assets
    stream = env['ir.binary']._get_stream_from(attachment, 'raw', filename)
             ^^^^^^^^^^^^^^^^^^^^^^^^^^^^^^^^^^^^^^^^^^^^^^^^^^^^^^^^^^^^^^
  File "/usr/local/lib/python3.12/site-packages/odoo/addons/base/models/ir_binary.py", line 127, in _get_stream_from
    stream = self._record_to_stream(record, field_name)
             ^^^^^^^^^^^^^^^^^^^^^^^^^^^^^^^^^^^^^^^^^^
  File "/usr/local/lib/python3.12/site-packages/odoo/addons/base/models/ir_binary.py", line 74, in _record_to_stream
    return record._to_http_stream()
           ^^^^^^^^^^^^^^^^^^^^^^^^
  File "/usr/local/lib/python3.12/site-packages/odoo/addons/base/models/ir_attachment.py", line 797, in _to_http_stream
    stat = os.stat(stream.path)
           ^^^^^^^^^^^^^^^^^^^^
FileNotFoundError: [Errno 2] No such file or directory: '/volumes/data/filestore/testing/4a/4a2b926a8affea412de805d420481fc6ef1408f6'
2025-02-20 06:38:57,433 1 WARNING testing odoo.addons.base.models.ir_actions_report: wkhtmltopdf: Exit with code 1 due to network error: UnknownContentError

2025-02-20 06:38:57,461 1 ERROR testing odoo.http: Exception during request handling.
Traceback (most recent call last):
  File "/usr/local/lib/python3.12/site-packages/odoo/http.py", line 2371, in __call__
    response = request._serve_db()
               ^^^^^^^^^^^^^^^^^^^
  File "/usr/local/lib/python3.12/site-packages/odoo/http.py", line 1898, in _serve_db
    return self._transactioning(
           ^^^^^^^^^^^^^^^^^^^^^
  File "/usr/local/lib/python3.12/site-packages/odoo/http.py", line 1961, in _transactioning
    return service_model.retrying(func, env=self.env)
           ^^^^^^^^^^^^^^^^^^^^^^^^^^^^^^^^^^^^^^^^^^
  File "/usr/local/lib/python3.12/site-packages/odoo/service/model.py", line 137, in retrying
    result = func()
             ^^^^^^
  File "/usr/local/lib/python3.12/site-packages/odoo/http.py", line 1928, in _serve_ir_http
    response = self.dispatcher.dispatch(rule.endpoint, args)
               ^^^^^^^^^^^^^^^^^^^^^^^^^^^^^^^^^^^^^^^^^^^^^
  File "/usr/local/lib/python3.12/site-packages/odoo/http.py", line 2089, in dispatch
    return self.request.registry['ir.http']._dispatch(endpoint)
           ^^^^^^^^^^^^^^^^^^^^^^^^^^^^^^^^^^^^^^^^^^^^^^^^^^^^
  File "/usr/local/lib/python3.12/site-packages/odoo/addons/base/models/ir_http.py", line 329, in _dispatch
    result = endpoint(**request.params)
             ^^^^^^^^^^^^^^^^^^^^^^^^^^
  File "/usr/local/lib/python3.12/site-packages/odoo/http.py", line 727, in route_wrapper
    result = endpoint(self, *args, **params_ok)
             ^^^^^^^^^^^^^^^^^^^^^^^^^^^^^^^^^^
  File "/odoo/addons/web/controllers/binary.py", line 149, in content_assets
    stream = env['ir.binary']._get_stream_from(attachment, 'raw', filename)
             ^^^^^^^^^^^^^^^^^^^^^^^^^^^^^^^^^^^^^^^^^^^^^^^^^^^^^^^^^^^^^^
  File "/usr/local/lib/python3.12/site-packages/odoo/addons/base/models/ir_binary.py", line 127, in _get_stream_from
    stream = self._record_to_stream(record, field_name)
             ^^^^^^^^^^^^^^^^^^^^^^^^^^^^^^^^^^^^^^^^^^
  File "/usr/local/lib/python3.12/site-packages/odoo/addons/base/models/ir_binary.py", line 74, in _record_to_stream
    return record._to_http_stream()
           ^^^^^^^^^^^^^^^^^^^^^^^^
  File "/usr/local/lib/python3.12/site-packages/odoo/addons/base/models/ir_attachment.py", line 797, in _to_http_stream
    stat = os.stat(stream.path)
           ^^^^^^^^^^^^^^^^^^^^
FileNotFoundError: [Errno 2] No such file or directory: '/volumes/data/filestore/testing/4a/4a2b926a8affea412de805d420481fc6ef1408f6'
2025-02-20 06:38:58,511 1 ERROR testing odoo.http: Exception during request handling.
Traceback (most recent call last):
  File "/usr/local/lib/python3.12/site-packages/odoo/http.py", line 2371, in __call__
    response = request._serve_db()
               ^^^^^^^^^^^^^^^^^^^
  File "/usr/local/lib/python3.12/site-packages/odoo/http.py", line 1898, in _serve_db
    return self._transactioning(
           ^^^^^^^^^^^^^^^^^^^^^
  File "/usr/local/lib/python3.12/site-packages/odoo/http.py", line 1961, in _transactioning
    return service_model.retrying(func, env=self.env)
           ^^^^^^^^^^^^^^^^^^^^^^^^^^^^^^^^^^^^^^^^^^
  File "/usr/local/lib/python3.12/site-packages/odoo/service/model.py", line 137, in retrying
    result = func()
             ^^^^^^
  File "/usr/local/lib/python3.12/site-packages/odoo/http.py", line 1928, in _serve_ir_http
    response = self.dispatcher.dispatch(rule.endpoint, args)
               ^^^^^^^^^^^^^^^^^^^^^^^^^^^^^^^^^^^^^^^^^^^^^
  File "/usr/local/lib/python3.12/site-packages/odoo/http.py", line 2089, in dispatch
    return self.request.registry['ir.http']._dispatch(endpoint)
           ^^^^^^^^^^^^^^^^^^^^^^^^^^^^^^^^^^^^^^^^^^^^^^^^^^^^
  File "/usr/local/lib/python3.12/site-packages/odoo/addons/base/models/ir_http.py", line 329, in _dispatch
    result = endpoint(**request.params)
             ^^^^^^^^^^^^^^^^^^^^^^^^^^
  File "/usr/local/lib/python3.12/site-packages/odoo/http.py", line 727, in route_wrapper
    result = endpoint(self, *args, **params_ok)
             ^^^^^^^^^^^^^^^^^^^^^^^^^^^^^^^^^^
  File "/odoo/addons/web/controllers/binary.py", line 149, in content_assets
    stream = env['ir.binary']._get_stream_from(attachment, 'raw', filename)
             ^^^^^^^^^^^^^^^^^^^^^^^^^^^^^^^^^^^^^^^^^^^^^^^^^^^^^^^^^^^^^^
  File "/usr/local/lib/python3.12/site-packages/odoo/addons/base/models/ir_binary.py", line 127, in _get_stream_from
    stream = self._record_to_stream(record, field_name)
             ^^^^^^^^^^^^^^^^^^^^^^^^^^^^^^^^^^^^^^^^^^
  File "/usr/local/lib/python3.12/site-packages/odoo/addons/base/models/ir_binary.py", line 74, in _record_to_stream
    return record._to_http_stream()
           ^^^^^^^^^^^^^^^^^^^^^^^^
  File "/usr/local/lib/python3.12/site-packages/odoo/addons/base/models/ir_attachment.py", line 797, in _to_http_stream
    stat = os.stat(stream.path)
           ^^^^^^^^^^^^^^^^^^^^
FileNotFoundError: [Errno 2] No such file or directory: '/volumes/data/filestore/testing/4a/4a2b926a8affea412de805d420481fc6ef1408f6'
2025-02-20 06:38:59,577 1 WARNING testing odoo.addons.base.models.ir_actions_report: wkhtmltopdf: Exit with code 1 due to network error: UnknownContentError

2025-02-20 06:38:59,662 1 ERROR testing odoo.http: Exception during request handling.
Traceback (most recent call last):
  File "/usr/local/lib/python3.12/site-packages/odoo/http.py", line 2371, in __call__
    response = request._serve_db()
               ^^^^^^^^^^^^^^^^^^^
  File "/usr/local/lib/python3.12/site-packages/odoo/http.py", line 1898, in _serve_db
    return self._transactioning(
           ^^^^^^^^^^^^^^^^^^^^^
  File "/usr/local/lib/python3.12/site-packages/odoo/http.py", line 1961, in _transactioning
    return service_model.retrying(func, env=self.env)
           ^^^^^^^^^^^^^^^^^^^^^^^^^^^^^^^^^^^^^^^^^^
  File "/usr/local/lib/python3.12/site-packages/odoo/service/model.py", line 137, in retrying
    result = func()
             ^^^^^^
  File "/usr/local/lib/python3.12/site-packages/odoo/http.py", line 1928, in _serve_ir_http
    response = self.dispatcher.dispatch(rule.endpoint, args)
               ^^^^^^^^^^^^^^^^^^^^^^^^^^^^^^^^^^^^^^^^^^^^^
  File "/usr/local/lib/python3.12/site-packages/odoo/http.py", line 2089, in dispatch
    return self.request.registry['ir.http']._dispatch(endpoint)
           ^^^^^^^^^^^^^^^^^^^^^^^^^^^^^^^^^^^^^^^^^^^^^^^^^^^^
  File "/usr/local/lib/python3.12/site-packages/odoo/addons/base/models/ir_http.py", line 329, in _dispatch
    result = endpoint(**request.params)
             ^^^^^^^^^^^^^^^^^^^^^^^^^^
  File "/usr/local/lib/python3.12/site-packages/odoo/http.py", line 727, in route_wrapper
    result = endpoint(self, *args, **params_ok)
             ^^^^^^^^^^^^^^^^^^^^^^^^^^^^^^^^^^
  File "/odoo/addons/web/controllers/binary.py", line 149, in content_assets
    stream = env['ir.binary']._get_stream_from(attachment, 'raw', filename)
             ^^^^^^^^^^^^^^^^^^^^^^^^^^^^^^^^^^^^^^^^^^^^^^^^^^^^^^^^^^^^^^
  File "/usr/local/lib/python3.12/site-packages/odoo/addons/base/models/ir_binary.py", line 127, in _get_stream_from
    stream = self._record_to_stream(record, field_name)
             ^^^^^^^^^^^^^^^^^^^^^^^^^^^^^^^^^^^^^^^^^^
  File "/usr/local/lib/python3.12/site-packages/odoo/addons/base/models/ir_binary.py", line 74, in _record_to_stream
    return record._to_http_stream()
           ^^^^^^^^^^^^^^^^^^^^^^^^
  File "/usr/local/lib/python3.12/site-packages/odoo/addons/base/models/ir_attachment.py", line 797, in _to_http_stream
    stat = os.stat(stream.path)
           ^^^^^^^^^^^^^^^^^^^^
FileNotFoundError: [Errno 2] No such file or directory: '/volumes/data/filestore/testing/4a/4a2b926a8affea412de805d420481fc6ef1408f6'
2025-02-20 06:39:00,698 1 ERROR testing odoo.http: Exception during request handling.
Traceback (most recent call last):
  File "/usr/local/lib/python3.12/site-packages/odoo/http.py", line 2371, in __call__
    response = request._serve_db()
               ^^^^^^^^^^^^^^^^^^^
  File "/usr/local/lib/python3.12/site-packages/odoo/http.py", line 1898, in _serve_db
    return self._transactioning(
           ^^^^^^^^^^^^^^^^^^^^^
  File "/usr/local/lib/python3.12/site-packages/odoo/http.py", line 1961, in _transactioning
    return service_model.retrying(func, env=self.env)
           ^^^^^^^^^^^^^^^^^^^^^^^^^^^^^^^^^^^^^^^^^^
  File "/usr/local/lib/python3.12/site-packages/odoo/service/model.py", line 137, in retrying
    result = func()
             ^^^^^^
  File "/usr/local/lib/python3.12/site-packages/odoo/http.py", line 1928, in _serve_ir_http
    response = self.dispatcher.dispatch(rule.endpoint, args)
               ^^^^^^^^^^^^^^^^^^^^^^^^^^^^^^^^^^^^^^^^^^^^^
  File "/usr/local/lib/python3.12/site-packages/odoo/http.py", line 2089, in dispatch
    return self.request.registry['ir.http']._dispatch(endpoint)
           ^^^^^^^^^^^^^^^^^^^^^^^^^^^^^^^^^^^^^^^^^^^^^^^^^^^^
  File "/usr/local/lib/python3.12/site-packages/odoo/addons/base/models/ir_http.py", line 329, in _dispatch
    result = endpoint(**request.params)
             ^^^^^^^^^^^^^^^^^^^^^^^^^^
  File "/usr/local/lib/python3.12/site-packages/odoo/http.py", line 727, in route_wrapper
    result = endpoint(self, *args, **params_ok)
             ^^^^^^^^^^^^^^^^^^^^^^^^^^^^^^^^^^
  File "/odoo/addons/web/controllers/binary.py", line 149, in content_assets
    stream = env['ir.binary']._get_stream_from(attachment, 'raw', filename)
             ^^^^^^^^^^^^^^^^^^^^^^^^^^^^^^^^^^^^^^^^^^^^^^^^^^^^^^^^^^^^^^
  File "/usr/local/lib/python3.12/site-packages/odoo/addons/base/models/ir_binary.py", line 127, in _get_stream_from
    stream = self._record_to_stream(record, field_name)
             ^^^^^^^^^^^^^^^^^^^^^^^^^^^^^^^^^^^^^^^^^^
  File "/usr/local/lib/python3.12/site-packages/odoo/addons/base/models/ir_binary.py", line 74, in _record_to_stream
    return record._to_http_stream()
           ^^^^^^^^^^^^^^^^^^^^^^^^
  File "/usr/local/lib/python3.12/site-packages/odoo/addons/base/models/ir_attachment.py", line 797, in _to_http_stream
    stat = os.stat(stream.path)
           ^^^^^^^^^^^^^^^^^^^^
FileNotFoundError: [Errno 2] No such file or directory: '/volumes/data/filestore/testing/4a/4a2b926a8affea412de805d420481fc6ef1408f6'
2025-02-20 06:39:01,798 1 WARNING testing odoo.addons.base.models.ir_actions_report: wkhtmltopdf: Exit with code 1 due to network error: UnknownContentError

2025-02-20 06:39:01,831 1 ERROR testing odoo.http: Exception during request handling.
Traceback (most recent call last):
  File "/usr/local/lib/python3.12/site-packages/odoo/http.py", line 2371, in __call__
    response = request._serve_db()
               ^^^^^^^^^^^^^^^^^^^
  File "/usr/local/lib/python3.12/site-packages/odoo/http.py", line 1898, in _serve_db
    return self._transactioning(
           ^^^^^^^^^^^^^^^^^^^^^
  File "/usr/local/lib/python3.12/site-packages/odoo/http.py", line 1961, in _transactioning
    return service_model.retrying(func, env=self.env)
           ^^^^^^^^^^^^^^^^^^^^^^^^^^^^^^^^^^^^^^^^^^
  File "/usr/local/lib/python3.12/site-packages/odoo/service/model.py", line 137, in retrying
    result = func()
             ^^^^^^
  File "/usr/local/lib/python3.12/site-packages/odoo/http.py", line 1928, in _serve_ir_http
    response = self.dispatcher.dispatch(rule.endpoint, args)
               ^^^^^^^^^^^^^^^^^^^^^^^^^^^^^^^^^^^^^^^^^^^^^
  File "/usr/local/lib/python3.12/site-packages/odoo/http.py", line 2089, in dispatch
    return self.request.registry['ir.http']._dispatch(endpoint)
           ^^^^^^^^^^^^^^^^^^^^^^^^^^^^^^^^^^^^^^^^^^^^^^^^^^^^
  File "/usr/local/lib/python3.12/site-packages/odoo/addons/base/models/ir_http.py", line 329, in _dispatch
    result = endpoint(**request.params)
             ^^^^^^^^^^^^^^^^^^^^^^^^^^
  File "/usr/local/lib/python3.12/site-packages/odoo/http.py", line 727, in route_wrapper
    result = endpoint(self, *args, **params_ok)
             ^^^^^^^^^^^^^^^^^^^^^^^^^^^^^^^^^^
  File "/odoo/addons/web/controllers/binary.py", line 149, in content_assets
    stream = env['ir.binary']._get_stream_from(attachment, 'raw', filename)
             ^^^^^^^^^^^^^^^^^^^^^^^^^^^^^^^^^^^^^^^^^^^^^^^^^^^^^^^^^^^^^^
  File "/usr/local/lib/python3.12/site-packages/odoo/addons/base/models/ir_binary.py", line 127, in _get_stream_from
    stream = self._record_to_stream(record, field_name)
             ^^^^^^^^^^^^^^^^^^^^^^^^^^^^^^^^^^^^^^^^^^
  File "/usr/local/lib/python3.12/site-packages/odoo/addons/base/models/ir_binary.py", line 74, in _record_to_stream
    return record._to_http_stream()
           ^^^^^^^^^^^^^^^^^^^^^^^^
  File "/usr/local/lib/python3.12/site-packages/odoo/addons/base/models/ir_attachment.py", line 797, in _to_http_stream
    stat = os.stat(stream.path)
           ^^^^^^^^^^^^^^^^^^^^
FileNotFoundError: [Errno 2] No such file or directory: '/volumes/data/filestore/testing/4a/4a2b926a8affea412de805d420481fc6ef1408f6'
2025-02-20 06:39:02,891 1 ERROR testing odoo.http: Exception during request handling.
Traceback (most recent call last):
  File "/usr/local/lib/python3.12/site-packages/odoo/http.py", line 2371, in __call__
    response = request._serve_db()
               ^^^^^^^^^^^^^^^^^^^
  File "/usr/local/lib/python3.12/site-packages/odoo/http.py", line 1898, in _serve_db
    return self._transactioning(
           ^^^^^^^^^^^^^^^^^^^^^
  File "/usr/local/lib/python3.12/site-packages/odoo/http.py", line 1961, in _transactioning
    return service_model.retrying(func, env=self.env)
           ^^^^^^^^^^^^^^^^^^^^^^^^^^^^^^^^^^^^^^^^^^
  File "/usr/local/lib/python3.12/site-packages/odoo/service/model.py", line 137, in retrying
    result = func()
             ^^^^^^
  File "/usr/local/lib/python3.12/site-packages/odoo/http.py", line 1928, in _serve_ir_http
    response = self.dispatcher.dispatch(rule.endpoint, args)
               ^^^^^^^^^^^^^^^^^^^^^^^^^^^^^^^^^^^^^^^^^^^^^
  File "/usr/local/lib/python3.12/site-packages/odoo/http.py", line 2089, in dispatch
    return self.request.registry['ir.http']._dispatch(endpoint)
           ^^^^^^^^^^^^^^^^^^^^^^^^^^^^^^^^^^^^^^^^^^^^^^^^^^^^
  File "/usr/local/lib/python3.12/site-packages/odoo/addons/base/models/ir_http.py", line 329, in _dispatch
    result = endpoint(**request.params)
             ^^^^^^^^^^^^^^^^^^^^^^^^^^
  File "/usr/local/lib/python3.12/site-packages/odoo/http.py", line 727, in route_wrapper
    result = endpoint(self, *args, **params_ok)
             ^^^^^^^^^^^^^^^^^^^^^^^^^^^^^^^^^^
  File "/odoo/addons/web/controllers/binary.py", line 149, in content_assets
    stream = env['ir.binary']._get_stream_from(attachment, 'raw', filename)
             ^^^^^^^^^^^^^^^^^^^^^^^^^^^^^^^^^^^^^^^^^^^^^^^^^^^^^^^^^^^^^^
  File "/usr/local/lib/python3.12/site-packages/odoo/addons/base/models/ir_binary.py", line 127, in _get_stream_from
    stream = self._record_to_stream(record, field_name)
             ^^^^^^^^^^^^^^^^^^^^^^^^^^^^^^^^^^^^^^^^^^
  File "/usr/local/lib/python3.12/site-packages/odoo/addons/base/models/ir_binary.py", line 74, in _record_to_stream
    return record._to_http_stream()
           ^^^^^^^^^^^^^^^^^^^^^^^^
  File "/usr/local/lib/python3.12/site-packages/odoo/addons/base/models/ir_attachment.py", line 797, in _to_http_stream
    stat = os.stat(stream.path)
           ^^^^^^^^^^^^^^^^^^^^
FileNotFoundError: [Errno 2] No such file or directory: '/volumes/data/filestore/testing/4a/4a2b926a8affea412de805d420481fc6ef1408f6'
2025-02-20 06:39:04,091 1 WARNING testing odoo.addons.base.models.ir_actions_report: wkhtmltopdf: Exit with code 1 due to network error: UnknownContentError

2025-02-20 06:39:04,093 1 ERROR testing odoo.addons.base.tests.test_reports: ERROR: TestAggregatePdfReports.test_aggregate_report_with_some_resources_reloaded_from_attachment_with_multiple_page_report
Traceback (most recent call last):
  File "/usr/local/lib/python3.12/site-packages/odoo/addons/base/tests/test_reports.py", line 655, in test_aggregate_report_with_some_resources_reloaded_from_attachment_with_multiple_page_report
    self.assert_report_creation("base.test_report", self.partners, self.partners[1])
  File "/usr/local/lib/python3.12/site-packages/odoo/addons/base/tests/test_reports.py", line 677, in assert_report_creation
    aggregate_report_content, content_type = reports._render_qweb_pdf(report_ref, res_ids=records.ids)
                                             ^^^^^^^^^^^^^^^^^^^^^^^^^^^^^^^^^^^^^^^^^^^^^^^^^^^^^^^^^
  File "/usr/local/lib/python3.12/site-packages/odoo/addons/base/models/ir_actions_report.py", line 1012, in _render_qweb_pdf
    collected_streams, report_type = self._pre_render_qweb_pdf(report_ref, res_ids=res_ids, data=data)
                                     ^^^^^^^^^^^^^^^^^^^^^^^^^^^^^^^^^^^^^^^^^^^^^^^^^^^^^^^^^^^^^^^^^
  File "/usr/local/lib/python3.12/site-packages/odoo/addons/base/models/ir_actions_report.py", line 1003, in _pre_render_qweb_pdf
    return self._render_qweb_pdf_prepare_streams(report_ref, data, res_ids=res_ids), 'pdf'
           ^^^^^^^^^^^^^^^^^^^^^^^^^^^^^^^^^^^^^^^^^^^^^^^^^^^^^^^^^^^^^^^^^^^^^^^^
  File "/usr/local/lib/python3.12/site-packages/odoo/addons/base/models/ir_actions_report.py", line 928, in _render_qweb_pdf_prepare_streams
    outlines_pages = sorted(set(outlines_pages))
                            ^^^^^^^^^^^^^^^^^^^
TypeError: unhashable type: 'IndirectObject'

2025-02-20 06:39:46,469 1 WARNING testing odoo.addons.web.tests.test_click_everywhere.TestMenusAdminLight.test_01_click_apps_menus_as_admin: websocket-client module is not installed
2025-02-20 06:39:46,481 1 WARNING testing odoo.addons.web.tests.test_click_everywhere.TestMenusDemoLight.test_01_click_apps_menus_as_demo: websocket-client module is not installed
2025-02-20 06:39:47,666 1 WARNING testing odoo.addons.web.tests.test_js.WebSuite.test_hoot: websocket-client module is not installed
2025-02-20 06:39:47,667 1 WARNING testing odoo.addons.web.tests.test_js.WebSuite.test_qunit_desktop: websocket-client module is not installed
2025-02-20 06:39:47,668 1 WARNING testing odoo.addons.web.tests.test_js.WebSuite.test_unit_desktop: websocket-client module is not installed
2025-02-20 06:39:47,673 1 WARNING testing odoo.addons.web.tests.test_js.MobileWebSuite.test_qunit_mobile: websocket-client module is not installed
2025-02-20 06:39:47,674 1 WARNING testing odoo.addons.web.tests.test_js.MobileWebSuite.test_unit_mobile: websocket-client module is not installed
2025-02-20 06:39:47,686 1 WARNING testing odoo.addons.web.tests.test_login.TestUserSwitch.test_user_switch: websocket-client module is not installed
2025-02-20 06:39:48,566 1 WARNING testing odoo.addons.auth_totp.tests.test_totp.TestTOTP.test_totp: websocket-client module is not installed
2025-02-20 06:39:48,567 1 WARNING testing odoo.addons.auth_totp.tests.test_totp.TestTOTP.test_totp_administration: websocket-client module is not installed
2025-02-20 06:39:48,568 1 WARNING testing odoo.addons.auth_totp.tests.test_totp.TestTOTP.test_totp_authenticate: websocket-client module is not installed
2025-02-20 06:39:53,433 1 WARNING testing odoo.addons.bus.tests.test_ir_websocket.TestIrWebsocket: websocket-client module is not installed
2025-02-20 06:39:53,436 1 WARNING testing odoo.addons.bus.tests.test_websocket_caryall.TestWebsocketCaryall: websocket-client module is not installed
2025-02-20 06:39:53,439 1 WARNING testing odoo.addons.bus.tests.test_websocket_rate_limiting.TestWebsocketRateLimiting: websocket-client module is not installed
2025-02-20 06:39:53,764 1 WARNING testing odoo.addons.web_editor.tests.test_odoo_editor.TestOdooEditor.test_odoo_editor_suite: websocket-client module is not installed
2025-02-20 06:39:53,769 1 ERROR testing odoo.tests.result: 10 failed, 5 error(s) of 1248 tests when loading database 'testing'
